2022-10-10 23:16:57,557 INFO    StreamThr :1276462 [internal.py:wandb_internal():88] W&B internal server running at pid: 1276462, started at: 2022-10-10 23:16:57.556933
2022-10-10 23:16:57,558 DEBUG   HandlerThread:1276462 [handler.py:handle_request():138] handle_request: status
2022-10-10 23:16:57,559 DEBUG   SenderThread:1276462 [sender.py:send_request():317] send_request: status
2022-10-10 23:16:57,560 INFO    WriterThread:1276462 [datastore.py:open_for_write():75] open: /scratch/gpfs/ashwinee/dp-custom/dp_finetuning/wandb/offline-run-20221010_231657-12kgpayj/run-12kgpayj.wandb
2022-10-10 23:16:57,566 DEBUG   HandlerThread:1276462 [handler.py:handle_request():138] handle_request: run_start
2022-10-10 23:16:57,570 DEBUG   HandlerThread:1276462 [meta.py:__init__():34] meta init
2022-10-10 23:16:57,570 DEBUG   HandlerThread:1276462 [meta.py:__init__():49] meta init done
2022-10-10 23:16:57,570 DEBUG   HandlerThread:1276462 [meta.py:probe():215] probe
2022-10-10 23:16:57,576 DEBUG   HandlerThread:1276462 [git.py:repo():40] git repository is invalid
2022-10-10 23:16:57,577 DEBUG   HandlerThread:1276462 [meta.py:_save_pip():53] save pip
2022-10-10 23:16:57,577 DEBUG   HandlerThread:1276462 [meta.py:_save_pip():67] save pip done
2022-10-10 23:16:57,577 DEBUG   HandlerThread:1276462 [meta.py:_save_conda():74] save conda
2022-10-10 23:16:57,581 ERROR   HandlerThread:1276462 [meta.py:_save_conda():83] Error saving conda packages
Traceback (most recent call last):
  File "/scratch/gpfs/ashwinee/envs/opacus/lib/python3.8/site-packages/wandb/sdk/internal/meta.py", line 79, in _save_conda
    subprocess.call(
  File "/scratch/gpfs/ashwinee/envs/opacus/lib/python3.8/subprocess.py", line 340, in call
    with Popen(*popenargs, **kwargs) as p:
  File "/scratch/gpfs/ashwinee/envs/opacus/lib/python3.8/subprocess.py", line 858, in __init__
    self._execute_child(args, executable, preexec_fn, close_fds,
  File "/scratch/gpfs/ashwinee/envs/opacus/lib/python3.8/subprocess.py", line 1704, in _execute_child
    raise child_exception_type(errno_num, err_msg, err_filename)
FileNotFoundError: [Errno 2] No such file or directory: 'conda'
2022-10-10 23:16:57,582 DEBUG   HandlerThread:1276462 [meta.py:_save_conda():84] save conda done
2022-10-10 23:16:57,582 DEBUG   HandlerThread:1276462 [meta.py:probe():253] probe done
2022-10-10 23:17:07,327 DEBUG   HandlerThread:1276462 [handler.py:handle_request():138] handle_request: partial_history
2022-10-10 23:17:16,444 DEBUG   HandlerThread:1276462 [handler.py:handle_request():138] handle_request: partial_history
2022-10-10 23:17:25,496 DEBUG   HandlerThread:1276462 [handler.py:handle_request():138] handle_request: partial_history
2022-10-10 23:17:34,556 DEBUG   HandlerThread:1276462 [handler.py:handle_request():138] handle_request: partial_history
2022-10-10 23:17:43,616 DEBUG   HandlerThread:1276462 [handler.py:handle_request():138] handle_request: partial_history
2022-10-10 23:17:52,674 DEBUG   HandlerThread:1276462 [handler.py:handle_request():138] handle_request: partial_history
2022-10-10 23:18:01,819 DEBUG   HandlerThread:1276462 [handler.py:handle_request():138] handle_request: partial_history
2022-10-10 23:18:10,907 DEBUG   HandlerThread:1276462 [handler.py:handle_request():138] handle_request: partial_history
2022-10-10 23:18:20,046 DEBUG   HandlerThread:1276462 [handler.py:handle_request():138] handle_request: partial_history
